2023-04-10 18:08:16,162 - [WARNING] - utils.backoff_util - (backoff_util.py).inner(38) - Connection error caused by: ConnectionError(Connection error caused by: NewConnectionError(<urllib3.connection.HTTPConnection object at 0x110e97af0>: Failed to establish a new connection: [Errno 8] nodename nor servname provided, or not known))
2023-04-10 18:08:16,381 - [WARNING] - utils.backoff_util - (backoff_util.py).inner(38) - Connection error caused by: ConnectionError(Connection error caused by: NewConnectionError(<urllib3.connection.HTTPConnection object at 0x110e97a60>: Failed to establish a new connection: [Errno 8] nodename nor servname provided, or not known))
2023-04-10 18:08:16,796 - [WARNING] - utils.backoff_util - (backoff_util.py).inner(38) - Connection error caused by: ConnectionError(Connection error caused by: NewConnectionError(<urllib3.connection.HTTPConnection object at 0x110ebe110>: Failed to establish a new connection: [Errno 8] nodename nor servname provided, or not known))
2023-04-10 18:08:17,614 - [WARNING] - utils.backoff_util - (backoff_util.py).inner(38) - Connection error caused by: ConnectionError(Connection error caused by: NewConnectionError(<urllib3.connection.HTTPConnection object at 0x110ebfac0>: Failed to establish a new connection: [Errno 8] nodename nor servname provided, or not known))
2023-04-10 18:08:19,232 - [WARNING] - utils.backoff_util - (backoff_util.py).inner(38) - Connection error caused by: ConnectionError(Connection error caused by: NewConnectionError(<urllib3.connection.HTTPConnection object at 0x110ebf580>: Failed to establish a new connection: [Errno 8] nodename nor servname provided, or not known))
2023-04-10 18:08:22,449 - [WARNING] - utils.backoff_util - (backoff_util.py).inner(38) - Connection error caused by: ConnectionError(Connection error caused by: NewConnectionError(<urllib3.connection.HTTPConnection object at 0x110efd720>: Failed to establish a new connection: [Errno 8] nodename nor servname provided, or not known))
2023-04-10 18:08:28,872 - [WARNING] - utils.backoff_util - (backoff_util.py).inner(38) - Connection error caused by: ConnectionError(Connection error caused by: NewConnectionError(<urllib3.connection.HTTPConnection object at 0x110efe830>: Failed to establish a new connection: [Errno 8] nodename nor servname provided, or not known))
2023-04-10 18:08:38,898 - [WARNING] - utils.backoff_util - (backoff_util.py).inner(38) - Connection error caused by: ConnectionError(Connection error caused by: NewConnectionError(<urllib3.connection.HTTPConnection object at 0x110ebf550>: Failed to establish a new connection: [Errno 8] nodename nor servname provided, or not known))
2023-04-10 18:08:48,915 - [WARNING] - utils.backoff_util - (backoff_util.py).inner(38) - Connection error caused by: ConnectionError(Connection error caused by: NewConnectionError(<urllib3.connection.HTTPConnection object at 0x110f24220>: Failed to establish a new connection: [Errno 8] nodename nor servname provided, or not known))
2023-04-10 18:08:58,931 - [WARNING] - utils.backoff_util - (backoff_util.py).inner(38) - Connection error caused by: ConnectionError(Connection error caused by: NewConnectionError(<urllib3.connection.HTTPConnection object at 0x110f25360>: Failed to establish a new connection: [Errno 8] nodename nor servname provided, or not known))
